Workbook

Sheet data_quality_log
A1: Column | B1: Null_Count | C1: Note
A2: gdp_usd | B2: =COUNTBLANK(global_renewable_energy_transit!F2:F1295) -> 144 | C2: All 2025 rows — GDP data not yet published
A3: solar_yoy_growth_pct | B3: =COUNTBLANK(global_renewable_energy_transit!W2:W1295) -> 358 | C3: Pre-solar era (before 2015) plus inf values replaced in cleaning
A4: wind_yoy_growth_pct | B4: =COUNTBLANK(global_renewable_energy_transit!X2:X1295) -> 83 | C4: Pre-wind era plus inf values replaced in cleaning
A5: renewables_yoy_growth_pct | B5: =COUNTBLANK(global_renewable_energy_transit!Y2:Y1295) -> 1235 | C5: Only recent years available — sparse by design
A6: hydro_electricity_twh | B6: =COUNTBLANK(global_renewable_energy_transit!L2:L1295) -> 76 | C6: Missing for some countries — left as NULL for SQL
A7: policy_milestone | B7: =COUNTBLANK(global_renewable_energy_transit!Z2:Z1295) -> 1294 | C7: Sparse event column — only 59 real policy entries in dataset
A8: country + year combination | B8: 0 | C8: No duplicate rows — each country has exactly one row per year

Sheet global_renewable_energy_transit
A1: country | B1: region | C1: income_group | D1: year | E1: population | F1: gdp_usd | G1: total_electricity_generation_twh | H1: electricity_demand_twh | I1: solar_electricity_twh | J1: wind_electricity_twh | K1: renewables_electricity_twh | L1: hydro_electricity_twh | M1: nuclear_electricity_twh | N1: fossil_electricity_twh | O1: solar_share_pct | P1: wind_share_pct | Q1: renewables_share_pct | R1: fossil_share_pct | S1: low_carbon_share_pct | T1: carbon_intensity_gco2_kwh | U1: co2_saved_solar_wind_mt | V1: solar_yoy_growth_pct | W1: wind_yoy_growth_pct | X1: renewables_yoy_growth_pct | Y1: policy_milestone
A2: Algeria | B2: Africa | C2: Lower-middle | D2: 2000 | E2: 30903894 | F2: 208554150552 | G2: 25.4 | H2: 25.33 | I2: 0 | J2: 0 | K2: 0.05 | L2: 0.05 | M2: 0 | N2: 25.35 | O2: 0 | P2: 0 | Q2: 0.197 | R2: 99.803 | S2: 0.197 | T2: 638.58 | U2: 0
A3: Algeria | B3: Africa | C3: Lower-middle | D3: 2001 | E3: 31331226 | F3: 223420294027 | G3: 26.62 | H3: 26.57 | I3: 0 | J3: 0 | K3: 0.07 | L3: 0.07 | M3: 0 | N3: 26.55 | O3: 0 | P3: 0 | Q3: 0.263 | R3: 99.737 | S3: 0.263 | T3: 638.24 | U3: 0 | X3: 40
A4: Algeria | B4: Africa | C4: Lower-middle | D4: 2002 | E4: 31750832 | F4: 245360923720 | G4: 27.65 | H4: 27.63 | I4: 0 | J4: 0 | K4: 0.06 | L4: 0.06 | M4: 0 | N4: 27.59 | O4: 0 | P4: 0 | Q4: 0.217 | R4: 99.783 | S4: 0.217 | T4: 637.98 | U4: 0 | X4: -14.3
A5: Algeria | B5: Africa | C5: Lower-middle | D5: 2003 | E5: 32175813 | F5: 273568638765 | G5: 29.57 | H5: 29.58 | I5: 0 | J5: 0 | K5: 0.26 | L5: 0.26 | M5: 0 | N5: 29.31 | O5: 0 | P5: 0 | Q5: 0.879 | R5: 99.121 | S5: 0.879 | T5: 634.09 | U5: 0 | X5: 333.3
A6: Algeria | B6: Africa | C6: Lower-middle | D6: 2004 | E6: 32628286 | F6: 296773569597 | G6: 31.25 | H6: 31.26 | I6: 0 | J6: 0 | K6: 0.25 | L6: 0.25 | M6: 0 | N6: 31 | O6: 0 | P6: 0 | Q6: 0.8 | R6: 99.2 | S6: 0.8 | T6: 634.56 | U6: 0 | X6: -3.8
A7: Algeria | B7: Africa | C7: Lower-middle | D7: 2005 | E7: 33109258 | F7: 326854481030 | G7: 33.91 | H7: 33.99 | I7: 0 | J7: 0 | K7: 0.55 | L7: 0.55 | M7: 0 | N7: 33.36 | O7: 0 | P7: 0 | Q7: 1.622 | R7: 98.378 | S7: 1.622 | T7: 629.31 | U7: 0 | X7: 120
A8: Algeria | B8: Africa | C8: Lower-middle | D8: 2006 | E8: 33623505 | F8: 345705309468 | G8: 35.23 | H8: 35.31 | I8: 0 | J8: 0 | K8: 0.22 | L8: 0.22 | M8: 0 | N8: 35.01 | O8: 0 | P8: 0 | Q8: 0.624 | R8: 99.376 | S8: 0.624 | T8: 635.82 | U8: 0 | X8: -60
A9: Algeria | B9: Africa | C9: Lower-middle | D9: 2007 | E9: 34189420 | F9: 371665260161 | G9: 37.19 | H9: 37.2 | I9: 0 | J9: 0 | K9: 0.22 | L9: 0.22 | M9: 0 | N9: 36.97 | O9: 0 | P9: 0 | Q9: 0.592 | R9: 99.408 | S9: 0.592 | T9: 635.92 | U9: 0 | X9: 0
A10: Algeria | B10: Africa | C10: Lower-middle | D10: 2008 | E10: 34816963 | F10: 395658515586 | G10: 40.23 | H10: 40.18 | I10: 0 | J10: 0 | K10: 0.28 | L10: 0.28 | M10: 0 | N10: 39.95 | O10: 0 | P10: 0 | Q10: 0.696 | R10: 99.304 | S10: 0.696 | T10: 635.35 | U10: 0 | X10: 27.3
A11: Algeria | B11: Africa | C11: Lower-middle | D11: 2009 | E11: 35490442 | F11: 418247711085 | G11: 38.5 | H11: 38.47 | I11: 0 | J11: 0 | K11: 0.3 | L11: 0.3 | M11: 0 | N11: 38.2 | O11: 0 | P11: 0 | Q11: 0.779 | R11: 99.221 | S11: 0.779 | T11: 634.55 | U11: 0 | X11: 7.1
A12: Algeria | B12: Africa | C12: Lower-middle | D12: 2010 | E12: 36188237 | F12: 450705801593 | G12: 45.73 | H12: 45.66 | I12: 0 | J12: 0 | K12: 0.17 | L12: 0.17 | M12: 0 | N12: 45.56 | O12: 0 | P12: 0 | Q12: 0.372 | R12: 99.628 | S12: 0.372 | T12: 637 | U12: 0 | X12: -43.3
A13: Algeria | B13: Africa | C13: Lower-middle | D13: 2011 | E13: 36903374 | F13: 482028679734 | G13: 51.22 | H13: 51.08 | I13: 0 | J13: 0 | K13: 0.5 | L13: 0.5 | M13: 0 | N13: 50.72 | O13: 0 | P13: 0 | Q13: 0.976 | R13: 99.024 | S13: 0.976 | T13: 633.35 | U13: 0 | X13: 194.1
A14: Algeria | B14: Africa | C14: Lower-middle | D14: 2012 | E14: 37646165 | F14: 498417638719 | G14: 57.4 | H14: 57.35 | I14: 0 | J14: 0 | K14: 0.62 | L14: 0.62 | M14: 0 | N14: 56.78 | O14: 0 | P14: 0 | Q14: 1.08 | R14: 98.92 | S14: 1.08 | T14: 632.75 | U14: 0 | X14: 24
... A17: Algeria | B17: Africa | C17: Lower-middle | D17: 2015 | E17: 40019528 | F17: 551521739825 | G17: 68.84 | H17: 68.81 | I17: 0.06 | J17: 0.02 | K17: 0.22 | L17: 0.14 | M17: 0 | N17: 68.62 | O17: 0.087 | P17: 0.029 | Q17: 0.32 | R17: 99.68 | S17: 0.32 | T17: 637.42 | U17: 0.04 | X17: -12
A18: Algeria | B18: Africa | C18: Lower-middle | D18: 2016 | E18: 40850719 | F18: 569170418715 | G18: 71.04 | H18: 70.79 | I18: 0.09 | J18: 0.03 | K18: 0.34 | L18: 0.22 | M18: 0 | N18: 70.7 | O18: 0.127 | P18: 0.042 | Q18: 0.479 | R18: 99.521 | S18: 0.479 | T18: 636.4 | U18: 0.05 | V18: 50 | W18: 50 | X18: 54.5
A19: Algeria | B19: Africa | C19: Lower-middle | D19: 2017 | E19: 41689302 | F19: 577138830559 | G19: 76.07 | H19: 75.73 | I19: 0.57 | J19: 0.01 | K19: 0.64 | L19: 0.06 | M19: 0 | N19: 75.43 | O19: 0.749 | P19: 0.013 | Q19: 0.841 | R19: 99.159 | S19: 0.841 | T19: 634.15 | U19: 0.26 | V19: 533.3 | W19: -66.7 | X19: 88.2
A20: Algeria | B20: Africa | C20: Lower-middle | D20: 2018 | E20: 42505033 | F20: 584064441740 | G20: 76.75 | H20: 76.66 | I20: 0.69 | J20: 0.01 | K20: 0.82 | L20: 0.12 | M20: 0 | N20: 75.93 | O20: 0.899 | P20: 0.013 | Q20: 1.068 | R20: 98.932 | S20: 1.068 | T20: 632.7 | U20: 0.32 | V20: 21.1 | W20: 0 | X20: 28.1
A21: Algeria | B21: Africa | C21: Lower-middle | D21: 2019 | E21: 43294551 | F21: 589905104177 | G21: 81.61 | H21: 81.47 | I21: 0.71 | J21: 0.01 | K21: 0.87 | L21: 0.15 | M21: 0 | N21: 80.74 | O21: 0.87 | P21: 0.012 | Q21: 1.066 | R21: 98.934 | S21: 1.066 | T21: 632.77 | U21: 0.32 | V21: 2.9 | W21: 0 | X21: 6.1
A22: Algeria | B22: Africa | C22: Lower-middle | D22: 2020 | E22: 44042094 | F22: 559819958223 | G22: 79.37 | H22: 79.31 | I22: 0.82 | J22: 0.01 | K22: 0.88 | L22: 0.05 | M22: 0 | N22: 78.49 | O22: 1.033 | P22: 0.013 | Q22: 1.109 | R22: 98.891 | S22: 1.109 | T22: 632.61 | U22: 0.37 | V22: 15.5 | W22: 0 | X22: 1.1 | Y22: 27% renewables by 2030 plan
A23: Algeria | B23: Africa | C23: Lower-middle | D23: 2021 | E23: 44761099 | F23: 578853830170 | G23: 85.6 | H23: 84.45 | I23: 0.79 | J23: 0.01 | K23: 0.81 | L23: 0.01 | M23: 0 | N23: 84.79 | O23: 0.923 | P23: 0.012 | Q23: 0.946 | R23: 99.054 | S23: 0.946 | T23: 633.53 | U23: 0.36 | V23: -3.7 | W23: 0 | X23: -8
A24: Algeria | B24: Africa | C24: Lower-middle | D24: 2022 | E24: 45477391 | F24: 595820067103 | G24: 91.47 | H24: 88.9 | I24: 0.83 | J24: 0.01 | K24: 0.86 | L24: 0.02 | M24: 0 | N24: 90.61 | O24: 0.907 | P24: 0.011 | Q24: 0.94 | R24: 99.06 | S24: 0.94 | T24: 633.65 | U24: 0.38 | V24: 5.1 | W24: 0 | X24: 6.2
A25: Algeria | B25: Africa | C25: Lower-middle | D25: 2023 | E25: 46164222 | G25: 95.88 | H25: 93.44 | I25: 0.87 | J25: 0.02 | K25: 0.91 | L25: 0.02 | M25: 0 | N25: 94.97 | O25: 0.907 | P25: 0.021 | Q25: 0.949 | R25: 99.051 | S25: 0.949 | T25: 633.61 | U25: 0.4 | V25: 4.8 | W25: 100 | X25: 5.8
A26: Algeria | B26: Africa | C26: Lower-middle | D26: 2024 | E26: 46814302 | G26: 96.36 | H26: 93.84 | I26: 0.99 | J26: 0.02 | K26: 1.03 | L26: 0.02 | M26: 0 | N26: 95.33 | O26: 1.027 | P26: 0.021 | Q26: 1.069 | R26: 98.931 | S26: 1.069 | T26: 632.94 | U26: 0.45 | V26: 13.8 | W26: 0 | X26: 13.2
A27: Argentina | B27: South America | C27: Upper-middle | D27: 2000 | E27: 37213986 | F27: 536480965694 | G27: 88.98 | H27: 90.2 | I27: 0 | J27: 0.03 | K27: 29 | L27: 28.58 | M27: 6.18 | N27: 53.8 | O27: 0 | P27: 0.034 | Q27: 32.592 | R27: 60.463 | S27: 39.537 | T27: 355.47 | U27: 0.01
A28: Argentina | B28: South America | C28: Upper-middle | D28: 2001 | E28: 37624817 | F28: 514867255248 | G28: 90.14 | H28: 91.89 | I28: 0 | J28: 0.05 | K28: 36.99 | L28: 36.58 | M28: 7.06 | N28: 46.09 | O28: 0 | P28: 0.055 | Q28: 41.036 | R28: 51.132 | S28: 48.868 | T28: 302.09 | U28: 0.02 | W28: 66.7 | X28: 27.6
A29: Argentina | B29: South America | C29: Upper-middle | D29: 2002 | E29: 38029345 | F29: 460558541367 | G29: 84.59 | H29: 90.51 | I29: 0 | J29: 0.07 | K29: 36.38 | L29: 35.78 | M29: 5.82 | N29: 42.39 | O29: 0 | P29: 0.083 | Q29: 43.007 | R29: 50.112 | S29: 49.888 | T29: 294.83 | U29: 0.03 | W29: 40 | X29: -1.6
A30: Argentina | B30: South America | C30: Upper-middle | D30: 2003 | E30: 38424283 | F30: 503104157615 | G30: 92.07 | H30: 97.1 | I30: 0 | J30: 0.08 | K30: 34.76 | L30: 33.8 | M30: 7.57 | N30: 49.74 | O30: 0 | P30: 0.087 | Q30: 37.754 | R30: 54.024 | S30: 45.976 | T30: 316.39 | U30: 0.04 | W30: 14.3 | X30: -4.5
A31: Argentina | B31: South America | C31: Upper-middle | D31: 2004 | E31: 38815915 | F31: 550306327169 | G31: 100.26 | H31: 103.73 | I31: 0 | J31: 0.07 | K31: 31.4 | L31: 30.46 | M31: 7.87 | N31: 60.99 | O31: 0 | P31: 0.07 | Q31: 31.319 | R31: 60.832 | S31: 39.168 | T31: 357.67 | U31: 0.03 | W31: -12.5 | X31: -9.7
A32: Argentina | B32: South America | C32: Upper-middle | D32: 2005 | E32: 39216786 | F32: 601050418142 | G32: 105.75 | H32: 109.63 | I32: 0 | J32: 0.07 | K32: 35.21 | L32: 34.22 | M32: 6.87 | N32: 63.67 | O32: 0 | P32: 0.066 | Q32: 33.296 | R32: 60.208 | S32: 39.792 | T32: 357.16 | U32: 0.03 | W32: 0 | X32: 12.1
A33: Argentina | B33: South America | C33: Upper-middle | D33: 2006 | E33: 39622113 | F33: 652296814311 | G33: 113.43 | H33: 115.79 | I33: 0 | J33: 0.07 | K33: 39.14 | L33: 38.02 | M33: 7.72 | N33: 66.57 | O33: 0 | P33: 0.062 | Q33: 34.506 | R33: 58.688 | S33: 41.312 | T33: 349.91 | U33: 0.03 | W33: 0 | X33: 11.2
A34: Argentina | B34: South America | C34: Upper-middle | D34: 2007 | E34: 40016767 | F34: 714725198062 | G34: 113.52 | H34: 121.12 | I34: 0 | J34: 0.06 | K34: 32.35 | L34: 31.22 | M34: 7.25 | N34: 73.92 | O34: 0 | P34: 0.053 | Q34: 28.497 | R34: 65.116 | S34: 34.884 | T34: 388.04 | U34: 0.03 | W34: -14.3 | X34: -17.3
A35: Argentina | B35: South America | C35: Upper-middle | D35: 2008 | E35: 40424151 | F35: 747157417513 | G35: 121.91 | H35: 127.39 | I35: 0 | J35: 0.04 | K35: 32.45 | L35: 31.2 | M35: 7.39 | N35: 82.07 | O35: 0 | P35: 0.033 | Q35: 26.618 | R35: 67.32 | S35: 32.68 | T35: 400.62 | U35: 0.02 | W35: -33.3 | X35: 0.3
A36: Argentina | B36: South America | C36: Upper-middle | D36: 2009 | E36: 40854832 | F36: 705920838368 | G36: 122.32 | H36: 128.48 | I36: 0 | J36: 0.04 | K36: 35.85 | L36: 34.62 | M36: 8.18 | N36: 78.29 | O36: 0 | P36: 0.033 | Q36: 29.308 | R36: 64.004 | S36: 35.996 | T36: 382.36 | U36: 0.02 | W36: 0 | X36: 10.5
A37: Argentina | B37: South America | C37: Upper-middle | D37: 2010 | E37: 41288694 | F37: 785785170150 | G37: 126 | H37: 134.6 | I37: 0 | J37: 0.03 | K37: 34.77 | L37: 33.36 | M37: 7.21 | N37: 84.02 | O37: 0 | P37: 0.024 | Q37: 27.595 | R37: 66.683 | S37: 33.317 | T37: 401.59 | U37: 0.01 | W37: -25 | X37: -3
A38: Argentina | B38: South America | C38: Upper-middle | D38: 2011 | E38: 41730655 | F38: 837742673804 | G38: 129.49 | H38: 139.16 | I38: 0 | J38: 0.03 | K38: 32.61 | L38: 31.19 | M38: 6.4 | N38: 90.48 | O38: 0 | P38: 0.023 | Q38: 25.183 | R38: 69.874 | S38: 30.126 | T38: 419.88 | U38: 0.01 | W38: 0 | X38: -6.2
A39: Argentina | B39: South America | C39: Upper-middle | D39: 2012 | E39: 42161718 | F39: 829147409948 | G39: 136.02 | H39: 143.63 | I39: 0.01 | J39: 0.37 | K39: 30.99 | L39: 29.16 | M39: 6.4 | N39: 98.63 | O39: 0.007 | P39: 0.272 | Q39: 22.783 | R39: 72.511 | S39: 27.489 | T39: 432.14 | U39: 0.17 | W39: 1133.3 | X39: -5
A40: Argentina | B40: South America | C40: Upper-middle | D40: 2013 | E40: 42582453 | F40: 849088398588 | G40: 139.45 | H40: 147.51 | I40: 0.02 | J40: 0.45 | K40: 34.77 | L40: 32.77 | M40: 6.21 | N40: 98.47 | O40: 0.014 | P40: 0.323 | Q40: 24.934 | R40: 70.613 | S40: 29.387 | T40: 422.23 | U40: 0.21 | V40: 100 | W40: 21.6 | X40: 12.2
A41: Argentina | B41: South America | C41: Upper-middle | D41: 2014 | E41: 43024071 | F41: 827750786191 | G41: 138.54 | H41: 148.4 | I41: 0.02 | J41: 0.62 | K41: 34.54 | L41: 32.42 | M41: 5.51 | N41: 98.49 | O41: 0.014 | P41: 0.448 | Q41: 24.931 | R41: 71.091 | S41: 28.909 | T41: 424.14 | U41: 0.29 | V41: 0 | W41: 37.8 | X41: -0.7
A42: Argentina | B42: South America | C42: Upper-middle | D42: 2015 | E42: 43477011 | F42: 850356641236 | G42: 145.42 | H42: 154.38 | I42: 0.01 | J42: 0.59 | K42: 34.43 | L42: 32.34 | M42: 7.04 | N42: 103.95 | O42: 0.007 | P42: 0.406 | Q42: 23.676 | R42: 71.483 | S42: 28.517 | T42: 426.56 | U42: 0.27 | V42: -50 | W42: -4.8 | X42: -0.3
...

Sheet country_scorecard
A1: country | B1: renewables_2024 | C1: renewables_2000 | D1: change | E1: carbon_intensity_2024 | F1: transition_score
A2: Venezuela | B2: =AVERAGEIFS(global_renewable_energy_transit!Q:Q,global_renewable_energy_transit!A:A,A2,global_renewable_energy_transit!D:D,2024) -> 91.139 | C2: =AVERAGEIFS(global_renewable_energy_transit!Q:Q,global_renewable_energy_transit!A:A,A2,global_renewable_energy_transit!D:D,2000) -> 73.754 | D2: =B2-C2 -> 17.385 | E2: =AVERAGEIFS(global_renewable_energy_transit!S:S,global_renewable_energy_transit!A:A,A2,global_renewable_energy_transit!D:D,2024) -> 91.139 | F2: =((B2/100)*0.5)+((D2/100)*0.3)+((1-(E2/1000))*0.2) -> 0.6896222
A3: Norway | B3: =AVERAGEIFS(global_renewable_energy_transit!Q:Q,global_renewable_energy_transit!A:A,A3,global_renewable_energy_transit!D:D,2024) -> 98.606 | C3: =AVERAGEIFS(global_renewable_energy_transit!Q:Q,global_renewable_energy_transit!A:A,A3,global_renewable_energy_transit!D:D,2000) -> 99.712 | D3: =B3-C3 -> -1.106 | E3: =AVERAGEIFS(global_renewable_energy_transit!S:S,global_renewable_energy_transit!A:A,A3,global_renewable_energy_transit!D:D,2024) -> 98.606 | F3: =((B3/100)*0.5)+((D3/100)*0.3)+((1-(E3/1000))*0.2) -> 0.6699908
A4: Austria | B4: =AVERAGEIFS(global_renewable_energy_transit!Q:Q,global_renewable_energy_transit!A:A,A4,global_renewable_energy_transit!D:D,2024) -> 86.224 | C4: =AVERAGEIFS(global_renewable_energy_transit!Q:Q,global_renewable_energy_transit!A:A,A4,global_renewable_energy_transit!D:D,2000) -> 72.837 | D4: =B4-C4 -> 13.387 | E4: =AVERAGEIFS(global_renewable_energy_transit!S:S,global_renewable_energy_transit!A:A,A4,global_renewable_energy_transit!D:D,2024) -> 86.224 | F4: =((B4/100)*0.5)+((D4/100)*0.3)+((1-(E4/1000))*0.2) -> 0.6540362
A5: Germany | B5: =AVERAGEIFS(global_renewable_energy_transit!Q:Q,global_renewable_energy_transit!A:A,A5,global_renewable_energy_transit!D:D,2024) -> 58.642 | C5: =AVERAGEIFS(global_renewable_energy_transit!Q:Q,global_renewable_energy_transit!A:A,A5,global_renewable_energy_transit!D:D,2000) -> 6.224 | D5: =B5-C5 -> 52.418 | E5: =AVERAGEIFS(global_renewable_energy_transit!S:S,global_renewable_energy_transit!A:A,A5,global_renewable_energy_transit!D:D,2024) -> 58.642 | F5: =((B5/100)*0.5)+((D5/100)*0.3)+((1-(E5/1000))*0.2) -> 0.6387356
A6: Brazil | B6: =AVERAGEIFS(global_renewable_energy_transit!Q:Q,global_renewable_energy_transit!A:A,A6,global_renewable_energy_transit!D:D,2024) -> 87.333 | C6: =AVERAGEIFS(global_renewable_energy_transit!Q:Q,global_renewable_energy_transit!A:A,A6,global_renewable_energy_transit!D:D,2000) -> 89.491 | D6: =B6-C6 -> -2.158 | E6: =AVERAGEIFS(global_renewable_energy_transit!S:S,global_renewable_energy_transit!A:A,A6,global_renewable_energy_transit!D:D,2024) -> 89.449 | F6: =((B6/100)*0.5)+((D6/100)*0.3)+((1-(E6/1000))*0.2) -> 0.6123012
A7: Chile | B7: =AVERAGEIFS(global_renewable_energy_transit!Q:Q,global_renewable_energy_transit!A:A,A7,global_renewable_energy_transit!D:D,2024) -> 70.041 | C7: =AVERAGEIFS(global_renewable_energy_transit!Q:Q,global_renewable_energy_transit!A:A,A7,global_renewable_energy_transit!D:D,2000) -> 49.83 | D7: =B7-C7 -> 20.211 | E7: =AVERAGEIFS(global_renewable_energy_transit!S:S,global_renewable_energy_transit!A:A,A7,global_renewable_energy_transit!D:D,2024) -> 70.041 | F7: =((B7/100)*0.5)+((D7/100)*0.3)+((1-(E7/1000))*0.2) -> 0.5968298
A8: Spain | B8: =AVERAGEIFS(global_renewable_energy_transit!Q:Q,global_renewable_energy_transit!A:A,A8,global_renewable_energy_transit!D:D,2024) -> 57.336 | C8: =AVERAGEIFS(global_renewable_energy_transit!Q:Q,global_renewable_energy_transit!A:A,A8,global_renewable_energy_transit!D:D,2000) -> 15.612 | D8: =B8-C8 -> 41.724 | E8: =AVERAGEIFS(global_renewable_energy_transit!S:S,global_renewable_energy_transit!A:A,A8,global_renewable_energy_transit!D:D,2024) -> 76.746 | F8: =((B8/100)*0.5)+((D8/100)*0.3)+((1-(E8/1000))*0.2) -> 0.5965028
A9: Netherlands | B9: =AVERAGEIFS(global_renewable_energy_transit!Q:Q,global_renewable_energy_transit!A:A,A9,global_renewable_energy_transit!D:D,2024) -> 50.74 | C9: =AVERAGEIFS(global_renewable_energy_transit!Q:Q,global_renewable_energy_transit!A:A,A9,global_renewable_energy_transit!D:D,2000) -> 3.373 | D9: =B9-C9 -> 47.367 | E9: =AVERAGEIFS(global_renewable_energy_transit!S:S,global_renewable_energy_transit!A:A,A9,global_renewable_energy_transit!D:D,2024) -> 53.658 | F9: =((B9/100)*0.5)+((D9/100)*0.3)+((1-(E9/1000))*0.2) -> 0.5850694
A10: United Kingdom | B10: =AVERAGEIFS(global_renewable_energy_transit!Q:Q,global_renewable_energy_transit!A:A,A10,global_renewable_energy_transit!D:D,2024) -> 50.648 | C10: =AVERAGEIFS(global_renewable_energy_transit!Q:Q,global_renewable_energy_transit!A:A,A10,global_renewable_energy_transit!D:D,2000) -> 2.628 | D10: =B10-C10 -> 48.02 | E10: =AVERAGEIFS(global_renewable_energy_transit!S:S,global_renewable_energy_transit!A:A,A10,global_renewable_energy_transit!D:D,2024) -> 64.932 | F10: =((B10/100)*0.5)+((D10/100)*0.3)+((1-(E10/1000))*0.2) -> 0.5843136
A11: Sweden | B11: =AVERAGEIFS(global_renewable_energy_transit!Q:Q,global_renewable_energy_transit!A:A,A11,global_renewable_energy_transit!D:D,2024) -> 69.358 | C11: =AVERAGEIFS(global_renewable_energy_transit!Q:Q,global_renewable_energy_transit!A:A,A11,global_renewable_energy_transit!D:D,2000) -> 57.247 | D11: =B11-C11 -> 12.111 | E11: =AVERAGEIFS(global_renewable_energy_transit!S:S,global_renewable_energy_transit!A:A,A11,global_renewable_energy_transit!D:D,2024) -> 98.792 | F11: =((B11/100)*0.5)+((D11/100)*0.3)+((1-(E11/1000))*0.2) -> 0.5633646
A12: Switzerland | B12: =AVERAGEIFS(global_renewable_energy_transit!Q:Q,global_renewable_energy_transit!A:A,A12,global_renewable_energy_transit!D:D,2024) -> 67.449 | C12: =AVERAGEIFS(global_renewable_energy_transit!Q:Q,global_renewable_energy_transit!A:A,A12,global_renewable_energy_transit!D:D,2000) -> 56.987 | D12: =B12-C12 -> 10.462 | E12: =AVERAGEIFS(global_renewable_energy_transit!S:S,global_renewable_energy_transit!A:A,A12,global_renewable_energy_transit!D:D,2024) -> 98.099 | F12: =((B12/100)*0.5)+((D12/100)*0.3)+((1-(E12/1000))*0.2) -> 0.5490112
A13: Italy | B13: =AVERAGEIFS(global_renewable_energy_transit!Q:Q,global_renewable_energy_transit!A:A,A13,global_renewable_energy_transit!D:D,2024) -> 50.172 | C13: =AVERAGEIFS(global_renewable_energy_transit!Q:Q,global_renewable_energy_transit!A:A,A13,global_renewable_energy_transit!D:D,2000) -> 18.845 | D13: =B13-C13 -> 31.327 | E13: =AVERAGEIFS(global_renewable_energy_transit!S:S,global_renewable_energy_transit!A:A,A13,global_renewable_energy_transit!D:D,2024) -> 50.172 | F13: =((B13/100)*0.5)+((D13/100)*0.3)+((1-(E13/1000))*0.2) -> 0.5348066
... A51: Bangladesh | B51: =AVERAGEIFS(global_renewable_energy_transit!Q:Q,global_renewable_energy_transit!A:A,A51,global_renewable_energy_transit!D:D,2024) -> 1.887 | C51: =AVERAGEIFS(global_renewable_energy_transit!Q:Q,global_renewable_energy_transit!A:A,A51,global_renewable_energy_transit!D:D,2000) -> 5.897 | D51: =B51-C51 -> -4.01 | E51: =AVERAGEIFS(global_renewable_energy_transit!S:S,global_renewable_energy_transit!A:A,A51,global_renewable_energy_transit!D:D,2024) -> 1.887 | F51: =((B51/100)*0.5)+((D51/100)*0.3)+((1-(E51/1000))*0.2) -> 0.1970276
